<?xml version="1.0" ?>

<robot name="pyarm" xmlns:xacro="http://www.ros.org/wiki/xacro">
    <link name="base_link">
        <visual>
            <origin rpy="0 0 0" xyz="0 0 1"/>
            <geometry>
                <cylinder radius="2" length="2"/>
            </geometry>
        </visual>
    </link>

    <joint name="waist_joint" type="revolute">
        <axis xyz="0 0 1"/>
        <limit effort="1000" lower="-3.14" upper="3.14" velocity="0.5"/>
        <origin rpy="0 0 0" xyz="0 0 2"/>
        <parent link="base_link"/>
        <child link="shoulder_link"/>
    </joint>

    <link name="shoulder_link">
        <visual>
            <origin rpy="0 0 0" xyz="0 0 1" />
            <geometry>
                <cylinder radius="0.5" length="2"/>
            </geometry>
        </visual>
    </link>

    <joint name="shoulder_joint" type="revolute">
        <axis xyz="0 1 0"/>
        <limit effort="1000" lower="-1.57" upper="3.14" velocity="0.5"/>
        <origin rpy="0 0 0" xyz="0 0 2"/>
        <parent link="shoulder_link"/>
        <child link="elbow_link"/>
    </joint>

    <link name="elbow_link">
        <visual>
            <origin rpy="0 0 0" xyz="0 0 1"/>
            <geometry>
                <cylinder radius="0.2" length="2"/>
            </geometry>
        </visual>
    </link>

    <joint name="elbow_joint" type="revolute">
        <axis xyz="0 1 0"/>
        <limit effort="1000" lower="-3.14" upper="3.14" velocity="0.5"/>
        <origin rpy="0 0 0" xyz="0 0 2"/>
        <parent link="elbow_link"/>
        <child link="wrist_roll_link"/>
    </joint>

    <link name="wrist_roll_link">
        <visual>
            <origin rpy="0 0 0" xyz="0 0 1"/>
            <geometry>
                <cylinder radius="0.1" length="2"/>
            </geometry>
        </visual>
    </link>

    <joint name="wrist_roll_joint" type="revolute">
        <axis xyz="0 0 1"/>
        <limit effort="1000" lower="-3.14" upper="3.14" velocity="0.5"/>
        <origin rpy="0 0 0" xyz="0 0 2"/>
        <parent link="wrist_roll_link"/>
        <child link="wrist_pitch_link"/>
    </joint>

    <link name="wrist_pitch_link">
        <visual>
            <origin rpy="0 0 0" xyz="0 0 1"/>
            <geometry>
                <cylinder radius="0.1" length="2"/>
            </geometry>
        </visual>
    </link>

    <joint name="wrist_pitch_joint" type="revolute">
        <axis xyz="0 1 0"/>
        <limit effort="1000" lower="-3.14" upper="3.14" velocity="0.5"/>
        <origin rpy="0 0 0" xyz="0 0 2"/>
        <parent link="wrist_pitch_link"/>
        <child link="final_link"/>
    </joint>

    <link name="final_link">
        <visual>
            <origin rpy="0 0 0" xyz="0 0 1"/>
            <geometry>
                <cylinder radius="0.1" length="2"/>
            </geometry>
        </visual>
    </link>
</robot>